Workbook

Sheet 1 Assumptions
A1: EQUATOR RESOLUTION · UNIVERSITY & ACADEMIC PARTNERSHIP PROGRAMME
A2: Assumptions
A3: Every driver in the model lives here. Change a value in column C and the whole workbook recalculates. Amounts in INR, exclusive of taxes.
A6: A · Student programme pricing (per participant)
A7: Code | B7: Programme | C7: List | D7: Partner rate | E7: Floor | F7: Min cohort | G7: Max cohort
A8: T-40-S | B8: Basic Mediation Training, 40 hours | C8: 12500 | D8: 9500 | E8: 7500 | F8: 25 | G8: 30
A9: T-20-S | B9: Advanced Mediation Training, 20 hours | C9: 7500 | D9: 5500 | E9: 4500 | F9: 20 | G9: 24
A10: C-CERT | B10: Credit-bearing certificate course | C10: 14000 | D10: 11000 | E10: 8500 | F10: 30 | G10: 40
A11: W-FULL-S | B11: Workshop, full day | C11: 2800 | D11: 2200 | E11: 1500 | F11: 25 | G11: 45
A12: SCH-RES | B12: Residential school, 6 days | C12: 26000 | D12: 22000 | E12: 17500 | F12: 25 | G12: 40
A14: B · Institution-paid programme pricing (per programme)
A15: Code | B15: Programme | C15: List | D15: Floor | E15: Capacity
A16: T-FDP | B16: Faculty Development Programme, 5 days | C16: 350000 | D16: 260000 | E16: 30
A17: W-FULL-I | B17: Workshop, full day, block booking | C17: 65000 | D17: 45000 | E17: 45
A18: A-POSH | B18: Internal Committee training, 1 day | C18: 85000 | D18: 60000 | E18: 25
A19: A-SGRC | B19: Grievance & Ombudsperson workshop, 1 day | C19: 95000 | D19: 70000 | E19: 25
A20: ADV-A | B20: Institutional advisory retainer, comprehensive p.a. | C20: 360000 | D20: 270000 | E20: 0
A21: ADV-B | B21: Institutional advisory retainer, standard p.a. | C21: 180000 | D21: 135000 | E21: 0
A22: COACH-INTL | B22: Coaching, international competition, per team | C22: 225000 | D22: 160000 | E22: 0
A23: COACH-NAT | B23: Coaching, national competition, per team | C23: 110000 | D23: 80000 | E23: 0
A24: LIC-CURR | B24: Curriculum licence p.a. | C24: 125000 | D24: 75000 | E24: 0
A26: C · Cost drivers
A27: Ref | B27: Cost | C27: Basis | D27: Rate
A28: C1 | B28: Lead trainer, multi-day block | C28: per day | D28: 15000
A29: C2 | B29: Lead trainer, single marquee session | C29: per day | D29: 22000
A30: C3 | B30: Associate trainer | C30: per day | D30: 7500
A31: C4 | B31: Assessment and marking | C31: per script | D31: 350
A32: C5 | B32: Participant materials | C32: per participant | D32: 450
A33: C6 | B33: Certificate, printing, register | C33: per participant | D33: 120
A34: C7 | B34: Trainer travel, outstation return | C34: per trainer per trip | D34: 9000
A35: C8 | B35: Trainer accommodation | C35: per night | D35: 4500
A36: C9 | B36: Local conveyance | C36: per programme | D36: 5000
A37: C10 | B37: Programme management allocation | C37: per programme day | D37: 6500
A38: C11 | B38: Competition problem development | C38: per problem | D38: 120000
A39: C12 | B39: Judge honorarium | C39: per judge per day | D39: 5000
... A42: C15 | B42: Photography and documentation | C42: per event day | D42: 12000
A44: D · Revenue-share splits (Equator share)
A45: Programme | B45: Equator | C45: Institution
A46: T-40-S, T-20-S | B46: 0.7 | C46: 0.3
A47: C-CERT credit-bearing | B47: 0.65 | C47: 0.35
...

Sheet 2 Programme economics
A1: EQUATOR RESOLUTION · UNIVERSITY & ACADEMIC PARTNERSHIP PROGRAMME
A2: Programme unit economics
A3: Live formulas. The central finding is at row 30: the same student course earns ~30% locally and ~6% with outstation trainers.
A6: A · T-40-S Basic Mediation Training, student cohort
A7: Line | B7: Basis | C7: Local bench | D7: Outstation
A8: Cohort size | B8: participants | C8: 40 | D8: 40
A9: Partner rate per participant | B9: Assumptions A, T-40-S | C9: ='1 Assumptions'!$D$8 | D9: =C9
A10: Gross participant fees | B10: cohort x rate | C10: =C8*C9 | D10: =D8*D9
A11: Equator revenue share | B11: 70% | C11: =C10*'1 Assumptions'!$B$46 | D11: =D10*'1 Assumptions'!$B$46
A12: Lead trainer | B12: 5 days | C12: =5*'1 Assumptions'!$D$28 | D12: =5*'1 Assumptions'!$D$28
A13: Associate trainer | B13: 5 days | C13: =5*'1 Assumptions'!$D$30 | D13: =5*'1 Assumptions'!$D$30
A14: Materials | B14: per participant | C14: =C8*'1 Assumptions'!$D$32 | D14: =D8*'1 Assumptions'!$D$32
A15: Certificates | B15: per participant | C15: =C8*'1 Assumptions'!$D$33 | D15: =D8*'1 Assumptions'!$D$33
A16: Assessment and marking | B16: per script | C16: =C8*'1 Assumptions'!$D$31 | D16: =D8*'1 Assumptions'!$D$31
A17: Local conveyance | B17: per programme | C17: ='1 Assumptions'!$D$36 | D17: ='1 Assumptions'!$D$36
A18: Trainer travel | B18: 2 trainers | C18: 0 | D18: =2*'1 Assumptions'!$D$34
A19: Trainer accommodation | B19: 5 nights x 2 | C19: 0 | D19: =5*2*'1 Assumptions'!$D$35
A20: Programme management | B20: 5 days | C20: =5*'1 Assumptions'!$D$37 | D20: =5*'1 Assumptions'!$D$37
A21: Total direct cost | C21: =SUM(C12:C20) | D21: =SUM(D12:D20)
A22: CONTRIBUTION | C22: =C11-C21 | D22: =D11-D21
A23: Contribution margin | C23: =C22/C11 | D23: =D22/D11
A24: Travel and stay penalty | D24: =C22-D22
A26: B · Cohort sensitivity, T-40-S local bench
A27: Cohort | B27: Equator share | C27: Direct cost | D27: Contribution | E27: Margin
A28: 25 | B28: =A28*C9*'1 Assumptions'!$B$46 | C28: =5*'1 Assumptions'!$D$28+5*'1 Assumptions'!$D$30+A28*('1 Assumptions'!$D$32+'1 Assumptions'!$D$33+'1 Assumptions'!$D$31)+'1 Assumptions'!$D$36+5*'1 Assumptions'!$D$37 | D28: =B28-C28 | E28: =D28/B28
A29: 30 | B29: =A29*C9*'1 Assumptions'!$B$46 | C29: =5*'1 Assumptions'!$D$28+5*'1 Assumptions'!$D$30+A29*('1 Assumptions'!$D$32+'1 Assumptions'!$D$33+'1 Assumptions'!$D$31)+'1 Assumptions'!$D$36+5*'1 Assumptions'!$D$37 | D29: =B29-C29 | E29: =D29/B29
A30: 35 | B30: =A30*C9*'1 Assumptions'!$B$46 | C30: =5*'1 Assumptions'!$D$28+5*'1 Assumptions'!$D$30+A30*('1 Assumptions'!$D$32+'1 Assumptions'!$D$33+'1 Assumptions'!$D$31)+'1 Assumptions'!$D$36+5*'1 Assumptions'!$D$37 | D30: =B30-C30 | E30: =D30/B30
A31: 40 | B31: =A31*C9*'1 Assumptions'!$B$46 | C31: =5*'1 Assumptions'!$D$28+5*'1 Assumptions'!$D$30+A31*('1 Assumptions'!$D$32+'1 Assumptions'!$D$33+'1 Assumptions'!$D$31)+'1 Assumptions'!$D$36+5*'1 Assumptions'!$D$37 | D31: =B31-C31 | E31: =D31/B31
A32: 45 | B32: =A32*C9*'1 Assumptions'!$B$46 | C32: =5*'1 Assumptions'!$D$28+5*'1 Assumptions'!$D$30+A32*('1 Assumptions'!$D$32+'1 Assumptions'!$D$33+'1 Assumptions'!$D$31)+'1 Assumptions'!$D$36+5*'1 Assumptions'!$D$37 | D32: =B32-C32 | E32: =D32/B32
A34: C · Other programmes
A35: Programme | B35: Equator revenue | C35: Direct cost | D35: Contribution | E35: Margin
A36: T-FDP Faculty Development, 5 days, outstation | B36: ='1 Assumptions'!$C$16 | C36: =5*'1 Assumptions'!$D$28+5*'1 Assumptions'!$D$30+30*550+30*'1 Assumptions'!$D$33+2*'1 Assumptions'!$D$34+5*2*'1 Assumptions'!$D$35+5*'1 Assumptions'!$D$37 | D36: =B36-C36 | E36: =D36/B36
A37: COACH-INTL coaching, per team per season | B37: ='1 Assumptions'!$C$22 | C37: =10*3*'1 Assumptions'!$D$40+3*'1 Assumptions'!$D$39+5000+15000 | D37: =B37-C37 | E37: =D37/B37
A38: ADV-A advisory retainer, per annum | B38: ='1 Assumptions'!$C$20 | C38: =12*'1 Assumptions'!$D$41+4*'1 Assumptions'!$D$34+14000+16000 | D38: =B38-C38 | E38: =D38/B38
A39: LIC-CURR curriculum licence, per annum | B39: ='1 Assumptions'!$C$24 | C39: 15000 | D39: =B39-C39 | E39: =D39/B39
A40: W-FULL-I workshop, full day, block booking, 30 attending | B40: ='1 Assumptions'!$C$17 | C40: ='1 Assumptions'!$D$28+30*'1 Assumptions'!$D$32 | D40: =B40-C40 | E40: =D40/B40
A41: A-SGRC grievance workshop, 1 day, outstation | B41: ='1 Assumptions'!$C$19 | C41: ='1 Assumptions'!$D$29+25*'1 Assumptions'!$D$32+'1 Assumptions'!$D$34 | D41: =B41-C41 | E41: =D41/B41
A42: A-POSH Internal Committee training, 1 day, outstation | B42: ='1 Assumptions'!$C$18 | C42: ='1 Assumptions'!$D$29+25*'1 Assumptions'!$D$32+'1 Assumptions'!$D$34 | D42: =B42-C42 | E42: =D42/B42
A43: COACH-NAT coaching, national, per team | B43: ='1 Assumptions'!$C$23 | C43: =6*3*'1 Assumptions'!$D$40+2*'1 Assumptions'!$D$39+5000+10000 | D43: =B43-C43 | E43: =D43/B43

Sheet 3 Partnership P&L
A1: EQUATOR RESOLUTION · UNIVERSITY & ACADEMIC PARTNERSHIP PROGRAMME
A2: Partnership profit and loss by tier
A3: Steady state, year 2 onward. Change activity counts in column B to model a specific institution.
A6: TIER 1 ANCHOR
A7: Activity | B7: Number | C7: Revenue each | D7: Contribution each | E7: Total revenue | F7: Total contribution
A8: T-40-S cohorts of 40, local bench | B8: 2 | C8: 266000 | D8: 79200 | E8: =B8*C8 | F8: =B8*D8
A9: T-20-S cohort of 24 | B9: 1 | C9: 92400 | D9: 22400 | E9: =B9*C9 | F9: =B9*D9
A10: Faculty Development Programme | B10: 1 | C10: 350000 | D10: 121900 | E10: =B10*C10 | F10: =B10*D10
A11: Institutional workshops, full day | B11: 4 | C11: 65000 | D11: 37000 | E11: =B11*C11 | F11: =B11*D11
A12: Coaching, international teams | B12: 2 | C12: 225000 | D12: 130000 | E12: =B12*C12 | F12: =B12*D12
A13: Advisory retainer, comprehensive | B13: 1 | C13: 360000 | D13: 114000 | E13: =B13*C13 | F13: =B13*D13
A14: Residential summer school, Equator 60% share | B14: 1 | C14: 396000 | D14: 136000 | E14: =B14*C14 | F14: =B14*D14
A15: Competition hosted, cost-shared | B15: 1 | C15: 0 | D15: 0 | E15: =B15*C15 | F15: =B15*D15
A16: Total | E16: =SUM(E8:E15) | F16: =SUM(F8:F15)
A17: Contribution margin | F17: =F16/E16
A18: Less allocated partnership management | F18: -350000
A19: NET CONTRIBUTION | F19: =F16+F18
A21: TIER 2 PROGRAMME
A22: Activity | B22: Number | C22: Revenue each | D22: Contribution each | E22: Total revenue | F22: Total contribution
A23: T-40-S cohort of 40, local bench | B23: 1 | C23: 266000 | D23: 79200 | E23: =B23*C23 | F23: =B23*D23
A24: Faculty Development Programme, biennial | B24: 0.5 | C24: 350000 | D24: 121900 | E24: =B24*C24 | F24: =B24*D24
A25: Institutional workshops, full day | B25: 2 | C25: 65000 | D25: 37000 | E25: =B25*C25 | F25: =B25*D25
A26: Advisory retainer, standard | B26: 1 | C26: 180000 | D26: 52000 | E26: =B26*C26 | F26: =B26*D26
A27: Coaching, national team | B27: 1 | C27: 110000 | D27: 60000 | E27: =B27*C27 | F27: =B27*D27
A28: Regional competition round, cost-shared | B28: 1 | C28: 0 | D28: 0 | E28: =B28*C28 | F28: =B28*D28
A29: Total | E29: =SUM(E23:E28) | F29: =SUM(F23:F28)
A30: Contribution margin | F30: =F29/E29
A31: Less allocated partnership management | F31: -120000
A32: NET CONTRIBUTION | F32: =F29+F31
A34: TIER 3 ASSOCIATE
A35: Activity | B35: Number | C35: Revenue each | D35: Contribution each | E35: Total revenue | F35: Total contribution
A36: Competition entries | B36: 3 | C36: 7500 | D36: 4000 | E36: =B36*C36 | F36: =B36*D36
A37: Occasional workshop | B37: 1 | C37: 65000 | D37: 37000 | E37: =B37*C37 | F37: =B37*D37
A38: Guest lecture and webinars, free | B38: 1 | C38: 0 | D38: -18000 | E38: =B38*C38 | F38: =B38*D38
A39: Total | E39: =SUM(E36:E38) | F39: =SUM(F36:F38)
A40: Contribution margin | F40: =F39/E39
A41: Less allocated partnership management | F41: -25000
A42: NET CONTRIBUTION | F42: =F39+F41
A44: Payback on acquisition cost
A45: Measure | B45: Tier 1 | C45: Tier 2 | D45: Tier 3
...

Sheet 4 Competition model
A1: EQUATOR RESOLUTION · UNIVERSITY & ACADEMIC PARTNERSHIP PROGRAMME
A2: Competition financial model
A3: Edition 1 is expected to make a loss. Budget it as a marketing investment with a defined ceiling.
A6: Line | B6: Edition 1 | C6: Edition 2 | D6: Edition 3
A7: Team registrations, number | B7: 40 | C7: 52 | D7: 64
A8: Registration fee per team | B8: 7500 | C8: 8000 | D8: 8500
A9: Registration income | B9: =B7*B8 | C9: =C7*C8 | D9: =D7*D8
A10: Title sponsorship | B10: 400000 | C10: 700000 | D10: 1200000
A11: Associate sponsorship | B11: 300000 | C11: 700000 | D11: 1400000
A12: Round sponsorship | B12: 150000 | C12: 400000 | D12: 750000
A13: Award and hospitality sponsorship | B13: 0 | C13: 150000 | D13: 450000
A14: Delegate passes | B14: 0 | C14: 50000 | D14: 100000
A15: TOTAL INCOME | B15: =B9+SUM(B10:B14) | C15: =C9+SUM(C10:C14) | D15: =D9+SUM(D10:D14)
A16: Expenditure
A17: Problem development | B17: 120000 | C17: 130000 | D17: 140000
A18: Judge honoraria | B18: 150000 | C18: 190000 | D18: 240000
A19: Judge travel and hospitality | B19: 200000 | C19: 260000 | D19: 330000
A20: Prize money | B20: 150000 | C20: 250000 | D20: 400000
A21: Trophies, certificates, medals | B21: 60000 | C21: 80000 | D21: 100000
A22: Participant materials | B22: 40000 | C22: 55000 | D22: 70000
A23: Branding, production, signage | B23: 180000 | C23: 220000 | D23: 280000
A24: Photography and video | B24: 75000 | C24: 90000 | D24: 110000
A25: Hospitality, venue supplied by host | B25: 120000 | C25: 170000 | D25: 230000
A26: Staff and programme management | B26: 150000 | C26: 180000 | D26: 220000
A27: Contingency at 10% | B27: =0.1*SUM(B17:B26) | C27: =0.1*SUM(C17:C26) | D27: =0.1*SUM(D17:D26)
A28: TOTAL EXPENDITURE | B28: =SUM(B17:B27) | C28: =SUM(C17:C27) | D28: =SUM(D17:D27)
A29: OUTTURN | B29: =B15-B28 | C29: =C15-C28 | D29: =D15-D28
A31: Rule: do not launch an edition without the title sponsor and one associate contracted in writing.
A32: Rule: edition 1 loss ceiling is INR 2,50,000. Beyond that, reduce scope rather than proceed.

Sheet 5 Three-year portfolio
A1: EQUATOR RESOLUTION · UNIVERSITY & ACADEMIC PARTNERSHIP PROGRAMME
A2: Three-year portfolio
A3: Planning figures for target-setting, not forecasts. Re-base after the first full delivery cycle.
A6: Measure | B6: Year 1 | C6: Year 2 | D6: Year 3
A7: Tier 1 partnerships | B7: 2 | C7: 3 | D7: 5
A8: Tier 2 partnerships | B8: 4 | C8: 12 | D8: 18
A9: Tier 3 partnerships | B9: 6 | C9: 20 | D9: 45
A10: Students trained | B10: 250 | C10: 900 | D10: 2000
A11: Faculty trained | B11: 40 | C11: 120 | D11: 250
A12: Interns hosted | B12: 24 | C12: 70 | D12: 140
A13: Interns converted | B13: 2 | C13: 8 | D13: 20
A14: Certified trainers on the bench | B14: 12 | C14: 22 | D14: 35
A15: Advisory retainers active | B15: 2 | C15: 10 | D15: 22
A16: Coaching engagements | B16: 3 | C16: 12 | D16: 26
A17: Programme revenue | B17: 3800000 | C17: 15200000 | D17: 30500000
A18: Competition net result | B18: -220000 | C18: 110000 | D18: 654000
A19: Total revenue | B19: =B17+B18 | C19: =C17+C18 | D19: =D17+D18
A20: Blended contribution margin | B20: 0.3 | C20: 0.34 | D20: 0.36
A21: Contribution | B21: =B19*B20 | C21: =C19*C20 | D21: =D19*D20
A22: Programme fixed cost | B22: -4200000 | C22: -5800000 | D22: -7400000
A23: PROGRAMME RESULT | B23: =B21+B22 | C23: =C21+C22 | D23: =D21+D22
A25: The three levers that move year 2 from breakeven into profit, in order of effect:
A26: 1. Advisory retainers. Each adds ~INR 1.14 lakh of contribution, with no seasonality and no delivery infrastructure.
A27: 2. Coaching. 57.8% margin, deliverable online, scales without a trainer bench.
A28: 3. Local trainer bench density. Every city reaching four certified trainers converts student delivery from 6% to 30% margin.
