Workbook

Sheet Read Me
B2: Equator Resolution — Insurance Vertical Financial Model
B3: Unit economics, a 36-month build-up and three scenarios. Every yellow cell is an assumption you can change.
B6: HOW IT WORKS
B7: - 'Assumptions' drives everything. Change the yellow cells and every other sheet recalculates.
B8: - 'Unit Economics' shows contribution per matter and per insurer, by product.
B9: - 'Build-Up' is a 36-month P&L. 'Scenarios' flexes three cases off the same engine.
B11: THE HONEST POINT THIS MODEL MAKES
B12: Retail is loss-leading by design and does not become profitable at any realistic volume.
B13: The vertical works if — and only if — insurer subscriptions and batched settlement days land.
B14: If they do not, this vertical is a credibility asset for the platform, not a business.
B16: All figures in Indian rupees, exclusive of GST. Illustrative — not a forecast.

Sheet Assumptions
A1: Assumptions
A2: Change the yellow cells only.
B4: VOLUME (by month 36)
B5: Retail matters per month | C5: 320 | E5: Self-filed and referred
B6: Share of retail matters that are insurer-referred | C6: 0.45 | E6: Fee borne by the insurer
B7: Insurer subscribers | C7: 9 | E7: Across all tiers
B8: Batched settlement days per month | C8: 11 | E8: Across all subscribers
B9: Files settled per batched day | C9: 26 | E9: Capacity is 30
B10: Commercial matters per month | C10: 16 | E10: Ad valorem
B12: PRICE
B13: Retail — registration & triage | C13: 1500 | E13: Waived for insurer-referred and for waiver categories
B14: Retail — schedule build | C14: 2500
B15: Retail — average mediation fee | C15: 9000 | E15: Blended across the value bands
B16: Retail — settlement drafting & registration | C16: 3500
B17: Insurer — average annual subscription | C17: 3400000 | E17: Blended across tiers
B18: Insurer — per-case fee beyond the included volume | C18: 7500
B19: Batched day — insurer day rate (neutral + admin) | C19: 95000
B20: Batched day — per file settled | C20: 1500
B21: Commercial — average administrative fee | C21: 85000
B23: EFFECTIVE REALISATION
B24: Share of retail matters attracting a full fee waiver | C24: 0.28 | E24: Small claims, death claims, seniors, schemes
B25: Share of retail matters that settle | C25: 0.55
B26: Share of retail matters where the other side does not participate | C26: 0.18 | E26: Mediation fee refunded
B28: COST TO SERVE
B29: Case-manager cost per retail matter | C29: 2200 | E29: Loaded, ~2.5 hours
B30: Neutral fee per retail mediation | C30: 4500 | E30: Paid out of the mediation fee
B31: Cost per batched day (neutral + venue + admin) | C31: 62000
B32: Neutral fee per commercial mediation | C32: 130000
B33: Account management cost per insurer per year | C33: 900000
B35: FIXED COSTS (monthly, at scale)
B36: Leadership & legal | C36: 800000
B37: Case management team | C37: 1150000
B38: Panel management & training | C38: 320000
B39: Technology & hosting | C39: 480000 | E39: Includes the segregated health-data store
B40: Compliance, DPO & audit | C40: 320000 | E40: Higher than other verticals — health data
B41: Marketing & channel | C41: 420000
B42: Other overhead | C42: 260000
B44: RAMP
B45: Month volumes reach 100% | C45: 36 | E45: Linear ramp from month 4
B46: Month the first insurer protocol signs | C46: 8
...

Sheet Unit Economics
A1: Unit Economics
A2: Contribution per unit, by product. Live formulas off Assumptions.
B4: Product / line | C4: Revenue (₹) | D4: Direct cost (₹) | E4: Contribution (₹) | F4: Comment
B5: Retail matter — self-filed, settles | C5: =(Assumptions!$C$13+Assumptions!$C$14+Assumptions!$C$15+Assumptions!$C$16)*(1-Assumptions!$C$24) | D5: =Assumptions!$C$29+Assumptions!$C$30 | E5: =C5-D5 | F5: Thin by design. 28% of matters pay nothing at all
B6: Retail matter — self-filed, does not settle | C6: =(Assumptions!$C$13+Assumptions!$C$14)*(1-Assumptions!$C$24) | D6: =Assumptions!$C$29 | E6: =C6-D6 | F6: Mediation fee refunded where the other side does not participate
B7: Retail matter — insurer-referred | C7: =Assumptions!$C$18 | D7: =Assumptions!$C$29*0.7+Assumptions!$C$30 | E7: =C7-D7 | F7: Cheaper to serve — the claim file arrives complete
B8: Batched settlement day | C8: =Assumptions!$C$19+Assumptions!$C$20*Assumptions!$C$9 | D8: =Assumptions!$C$31 | E8: =C8-D8 | F8: The highest-margin product in the vertical
B9: Insurer subscription (annual) | C9: =Assumptions!$C$17 | D9: =Assumptions!$C$33 | E9: =C9-D9 | F9: Before per-case fees on volume beyond the included allowance
B10: Commercial matter | C10: =Assumptions!$C$21+Assumptions!$C$32 | D10: =Assumptions!$C$32+15000 | E10: =C10-D10 | F10: Neutral fee passes through; the administrative fee is the margin
B13: What this table says
B14: A self-filed retail matter contributes very little and, once a fee waiver applies, contributes nothing. That is intentional: the retail service buys credibility and volume, and credibility is what makes the insurer sale possible. The batched settlement day and the subscription are where the money is.

Sheet Build-Up
A1: 36-Month Build-Up
A2: All figures monthly, in rupees. Driven entirely by Assumptions.
B4: Month | C4: 1 | D4: 2 | E4: 3 | F4: 4 | G4: 5 | H4: 6 | I4: 7 | J4: 8 | K4: 9 | L4: 10 | M4: 11 | N4: 12 | O4: 13 | P4: 14 | Q4: 15 | R4: 16 | S4: 17 | T4: 18 | U4: 19 | V4: 20 | W4: 21 | X4: 22 | Y4: 23 | Z4: 24 | AA4: 25 | AB4: 26 | AC4: 27 | AD4: 28 | AE4: 29 | AF4: 30 | AG4: 31 | AH4: 32 | AI4: 33 | AJ4: 34 | AK4: 35 | AL4: 36
B5: Ramp factor | C5: =MIN(1,MAX(0,(1-3)/(Assumptions!$C$45-3))) | D5: =MIN(1,MAX(0,(2-3)/(Assumptions!$C$45-3))) | E5: =MIN(1,MAX(0,(3-3)/(Assumptions!$C$45-3))) | F5: =MIN(1,MAX(0,(4-3)/(Assumptions!$C$45-3))) | G5: =MIN(1,MAX(0,(5-3)/(Assumptions!$C$45-3))) | H5: =MIN(1,MAX(0,(6-3)/(Assumptions!$C$45-3))) | I5: =MIN(1,MAX(0,(7-3)/(Assumptions!$C$45-3))) | J5: =MIN(1,MAX(0,(8-3)/(Assumptions!$C$45-3))) | K5: =MIN(1,MAX(0,(9-3)/(Assumptions!$C$45-3))) | L5: =MIN(1,MAX(0,(10-3)/(Assumptions!$C$45-3))) | M5: =MIN(1,MAX(0,(11-3)/(Assumptions!$C$45-3))) | N5: =MIN(1,MAX(0,(12-3)/(Assumptions!$C$45-3))) | O5: =MIN(1,MAX(0,(13-3)/(Assumptions!$C$45-3))) | P5: =MIN(1,MAX(0,(14-3)/(Assumptions!$C$45-3))) | Q5: =MIN(1,MAX(0,(15-3)/(Assumptions!$C$45-3))) | R5: =MIN(1,MAX(0,(16-3)/(Assumptions!$C$45-3))) | S5: =MIN(1,MAX(0,(17-3)/(Assumptions!$C$45-3))) | T5: =MIN(1,MAX(0,(18-3)/(Assumptions!$C$45-3))) | U5: =MIN(1,MAX(0,(19-3)/(Assumptions!$C$45-3))) | V5: =MIN(1,MAX(0,(20-3)/(Assumptions!$C$45-3))) | W5: =MIN(1,MAX(0,(21-3)/(Assumptions!$C$45-3))) | X5: =MIN(1,MAX(0,(22-3)/(Assumptions!$C$45-3))) | Y5: =MIN(1,MAX(0,(23-3)/(Assumptions!$C$45-3))) | Z5: =MIN(1,MAX(0,(24-3)/(Assumptions!$C$45-3))) | AA5: =MIN(1,MAX(0,(25-3)/(Assumptions!$C$45-3))) | AB5: =MIN(1,MAX(0,(26-3)/(Assumptions!$C$45-3))) | AC5: =MIN(1,MAX(0,(27-3)/(Assumptions!$C$45-3))) | AD5: =MIN(1,MAX(0,(28-3)/(Assumptions!$C$45-3))) | AE5: =MIN(1,MAX(0,(29-3)/(Assumptions!$C$45-3))) | AF5: =MIN(1,MAX(0,(30-3)/(Assumptions!$C$45-3))) | AG5: =MIN(1,MAX(0,(31-3)/(Assumptions!$C$45-3))) | AH5: =MIN(1,MAX(0,(32-3)/(Assumptions!$C$45-3))) | AI5: =MIN(1,MAX(0,(33-3)/(Assumptions!$C$45-3))) | AJ5: =MIN(1,MAX(0,(34-3)/(Assumptions!$C$45-3))) | AK5: =MIN(1,MAX(0,(35-3)/(Assumptions!$C$45-3))) | AL5: =MIN(1,MAX(0,(36-3)/(Assumptions!$C$45-3)))
B6: Retail matters | C6: =Assumptions!$C$5*C5 | D6: =Assumptions!$C$5*D5 | E6: =Assumptions!$C$5*E5 | F6: =Assumptions!$C$5*F5 | G6: =Assumptions!$C$5*G5 | H6: =Assumptions!$C$5*H5 | I6: =Assumptions!$C$5*I5 | J6: =Assumptions!$C$5*J5 | ... AL6: =Assumptions!$C$5*AL5
B7: — of which insurer-referred | C7: =C6*Assumptions!$C$6 | D7: =D6*Assumptions!$C$6 | E7: =E6*Assumptions!$C$6 | F7: =F6*Assumptions!$C$6 | G7: =G6*Assumptions!$C$6 | H7: =H6*Assumptions!$C$6 | I7: =I6*Assumptions!$C$6 | J7: =J6*Assumptions!$C$6 | ... AL7: =AL6*Assumptions!$C$6
B8: — of which self-filed | C8: =C6-C7 | D8: =D6-D7 | E8: =E6-E7 | F8: =F6-F7 | G8: =G6-G7 | H8: =H6-H7 | I8: =I6-I7 | J8: =J6-J7 | ... AL8: =AL6-AL7
B9: Insurer subscribers | C9: =MIN(Assumptions!$C$7,MAX(0,ROUNDDOWN((1-Assumptions!$C$46)/Assumptions!$C$47,0)+1)) | D9: =MIN(Assumptions!$C$7,MAX(0,ROUNDDOWN((2-Assumptions!$C$46)/Assumptions!$C$47,0)+1)) | E9: =MIN(Assumptions!$C$7,MAX(0,ROUNDDOWN((3-Assumptions!$C$46)/Assumptions!$C$47,0)+1)) | F9: =MIN(Assumptions!$C$7,MAX(0,ROUNDDOWN((4-Assumptions!$C$46)/Assumptions!$C$47,0)+1)) | G9: =MIN(Assumptions!$C$7,MAX(0,ROUNDDOWN((5-Assumptions!$C$46)/Assumptions!$C$47,0)+1)) | H9: =MIN(Assumptions!$C$7,MAX(0,ROUNDDOWN((6-Assumptions!$C$46)/Assumptions!$C$47,0)+1)) | I9: =MIN(Assumptions!$C$7,MAX(0,ROUNDDOWN((7-Assumptions!$C$46)/Assumptions!$C$47,0)+1)) | J9: =MIN(Assumptions!$C$7,MAX(0,ROUNDDOWN((8-Assumptions!$C$46)/Assumptions!$C$47,0)+1)) | K9: =MIN(Assumptions!$C$7,MAX(0,ROUNDDOWN((9-Assumptions!$C$46)/Assumptions!$C$47,0)+1)) | L9: =MIN(Assumptions!$C$7,MAX(0,ROUNDDOWN((10-Assumptions!$C$46)/Assumptions!$C$47,0)+1)) | M9: =MIN(Assumptions!$C$7,MAX(0,ROUNDDOWN((11-Assumptions!$C$46)/Assumptions!$C$47,0)+1)) | N9: =MIN(Assumptions!$C$7,MAX(0,ROUNDDOWN((12-Assumptions!$C$46)/Assumptions!$C$47,0)+1)) | O9: =MIN(Assumptions!$C$7,MAX(0,ROUNDDOWN((13-Assumptions!$C$46)/Assumptions!$C$47,0)+1)) | P9: =MIN(Assumptions!$C$7,MAX(0,ROUNDDOWN((14-Assumptions!$C$46)/Assumptions!$C$47,0)+1)) | Q9: =MIN(Assumptions!$C$7,MAX(0,ROUNDDOWN((15-Assumptions!$C$46)/Assumptions!$C$47,0)+1)) | R9: =MIN(Assumptions!$C$7,MAX(0,ROUNDDOWN((16-Assumptions!$C$46)/Assumptions!$C$47,0)+1)) | S9: =MIN(Assumptions!$C$7,MAX(0,ROUNDDOWN((17-Assumptions!$C$46)/Assumptions!$C$47,0)+1)) | T9: =MIN(Assumptions!$C$7,MAX(0,ROUNDDOWN((18-Assumptions!$C$46)/Assumptions!$C$47,0)+1)) | U9: =MIN(Assumptions!$C$7,MAX(0,ROUNDDOWN((19-Assumptions!$C$46)/Assumptions!$C$47,0)+1)) | V9: =MIN(Assumptions!$C$7,MAX(0,ROUNDDOWN((20-Assumptions!$C$46)/Assumptions!$C$47,0)+1)) | W9: =MIN(Assumptions!$C$7,MAX(0,ROUNDDOWN((21-Assumptions!$C$46)/Assumptions!$C$47,0)+1)) | X9: =MIN(Assumptions!$C$7,MAX(0,ROUNDDOWN((22-Assumptions!$C$46)/Assumptions!$C$47,0)+1)) | Y9: =MIN(Assumptions!$C$7,MAX(0,ROUNDDOWN((23-Assumptions!$C$46)/Assumptions!$C$47,0)+1)) | Z9: =MIN(Assumptions!$C$7,MAX(0,ROUNDDOWN((24-Assumptions!$C$46)/Assumptions!$C$47,0)+1)) | AA9: =MIN(Assumptions!$C$7,MAX(0,ROUNDDOWN((25-Assumptions!$C$46)/Assumptions!$C$47,0)+1)) | AB9: =MIN(Assumptions!$C$7,MAX(0,ROUNDDOWN((26-Assumptions!$C$46)/Assumptions!$C$47,0)+1)) | AC9: =MIN(Assumptions!$C$7,MAX(0,ROUNDDOWN((27-Assumptions!$C$46)/Assumptions!$C$47,0)+1)) | AD9: =MIN(Assumptions!$C$7,MAX(0,ROUNDDOWN((28-Assumptions!$C$46)/Assumptions!$C$47,0)+1)) | AE9: =MIN(Assumptions!$C$7,MAX(0,ROUNDDOWN((29-Assumptions!$C$46)/Assumptions!$C$47,0)+1)) | AF9: =MIN(Assumptions!$C$7,MAX(0,ROUNDDOWN((30-Assumptions!$C$46)/Assumptions!$C$47,0)+1)) | AG9: =MIN(Assumptions!$C$7,MAX(0,ROUNDDOWN((31-Assumptions!$C$46)/Assumptions!$C$47,0)+1)) | AH9: =MIN(Assumptions!$C$7,MAX(0,ROUNDDOWN((32-Assumptions!$C$46)/Assumptions!$C$47,0)+1)) | AI9: =MIN(Assumptions!$C$7,MAX(0,ROUNDDOWN((33-Assumptions!$C$46)/Assumptions!$C$47,0)+1)) | AJ9: =MIN(Assumptions!$C$7,MAX(0,ROUNDDOWN((34-Assumptions!$C$46)/Assumptions!$C$47,0)+1)) | AK9: =MIN(Assumptions!$C$7,MAX(0,ROUNDDOWN((35-Assumptions!$C$46)/Assumptions!$C$47,0)+1)) | AL9: =MIN(Assumptions!$C$7,MAX(0,ROUNDDOWN((36-Assumptions!$C$46)/Assumptions!$C$47,0)+1))
B10: Batched days | C10: =Assumptions!$C$8*C5*(C9/MAX(1,Assumptions!$C$7)) | D10: =Assumptions!$C$8*D5*(D9/MAX(1,Assumptions!$C$7)) | E10: =Assumptions!$C$8*E5*(E9/MAX(1,Assumptions!$C$7)) | F10: =Assumptions!$C$8*F5*(F9/MAX(1,Assumptions!$C$7)) | G10: =Assumptions!$C$8*G5*(G9/MAX(1,Assumptions!$C$7)) | H10: =Assumptions!$C$8*H5*(H9/MAX(1,Assumptions!$C$7)) | I10: =Assumptions!$C$8*I5*(I9/MAX(1,Assumptions!$C$7)) | J10: =Assumptions!$C$8*J5*(J9/MAX(1,Assumptions!$C$7)) | ... AL10: =Assumptions!$C$8*AL5*(AL9/MAX(1,Assumptions!$C$7))
B11: Commercial matters | C11: =Assumptions!$C$10*C5 | D11: =Assumptions!$C$10*D5 | E11: =Assumptions!$C$10*E5 | F11: =Assumptions!$C$10*F5 | G11: =Assumptions!$C$10*G5 | H11: =Assumptions!$C$10*H5 | I11: =Assumptions!$C$10*I5 | J11: =Assumptions!$C$10*J5 | ... AL11: =Assumptions!$C$10*AL5
B13: REVENUE
B14: Retail — self-filed | C14: =C8*'Unit Economics'!$C$5*Assumptions!$C$25+C8*'Unit Economics'!$C$6*(1-Assumptions!$C$25) | D14: =D8*'Unit Economics'!$C$5*Assumptions!$C$25+D8*'Unit Economics'!$C$6*(1-Assumptions!$C$25) | E14: =E8*'Unit Economics'!$C$5*Assumptions!$C$25+E8*'Unit Economics'!$C$6*(1-Assumptions!$C$25) | F14: =F8*'Unit Economics'!$C$5*Assumptions!$C$25+F8*'Unit Economics'!$C$6*(1-Assumptions!$C$25) | G14: =G8*'Unit Economics'!$C$5*Assumptions!$C$25+G8*'Unit Economics'!$C$6*(1-Assumptions!$C$25) | H14: =H8*'Unit Economics'!$C$5*Assumptions!$C$25+H8*'Unit Economics'!$C$6*(1-Assumptions!$C$25) | I14: =I8*'Unit Economics'!$C$5*Assumptions!$C$25+I8*'Unit Economics'!$C$6*(1-Assumptions!$C$25) | J14: =J8*'Unit Economics'!$C$5*Assumptions!$C$25+J8*'Unit Economics'!$C$6*(1-Assumptions!$C$25) | ... AL14: =AL8*'Unit Economics'!$C$5*Assumptions!$C$25+AL8*'Unit Economics'!$C$6*(1-Assumptions!$C$25)
B15: Retail — insurer-referred | C15: =C7*'Unit Economics'!$C$7 | D15: =D7*'Unit Economics'!$C$7 | E15: =E7*'Unit Economics'!$C$7 | F15: =F7*'Unit Economics'!$C$7 | G15: =G7*'Unit Economics'!$C$7 | H15: =H7*'Unit Economics'!$C$7 | I15: =I7*'Unit Economics'!$C$7 | J15: =J7*'Unit Economics'!$C$7 | ... AL15: =AL7*'Unit Economics'!$C$7
B16: Insurer subscriptions | C16: =C9*Assumptions!$C$17/12 | D16: =D9*Assumptions!$C$17/12 | E16: =E9*Assumptions!$C$17/12 | F16: =F9*Assumptions!$C$17/12 | G16: =G9*Assumptions!$C$17/12 | H16: =H9*Assumptions!$C$17/12 | I16: =I9*Assumptions!$C$17/12 | J16: =J9*Assumptions!$C$17/12 | ... AL16: =AL9*Assumptions!$C$17/12
B17: Batched settlement days | C17: =C10*'Unit Economics'!$C$8 | D17: =D10*'Unit Economics'!$C$8 | E17: =E10*'Unit Economics'!$C$8 | F17: =F10*'Unit Economics'!$C$8 | G17: =G10*'Unit Economics'!$C$8 | H17: =H10*'Unit Economics'!$C$8 | I17: =I10*'Unit Economics'!$C$8 | J17: =J10*'Unit Economics'!$C$8 | ... AL17: =AL10*'Unit Economics'!$C$8
B18: Commercial | C18: =C11*'Unit Economics'!$C$10 | D18: =D11*'Unit Economics'!$C$10 | E18: =E11*'Unit Economics'!$C$10 | F18: =F11*'Unit Economics'!$C$10 | G18: =G11*'Unit Economics'!$C$10 | H18: =H11*'Unit Economics'!$C$10 | I18: =I11*'Unit Economics'!$C$10 | J18: =J11*'Unit Economics'!$C$10 | ... AL18: =AL11*'Unit Economics'!$C$10
B19: Total revenue | C19: =SUM(C14:C18) | D19: =SUM(D14:D18) | E19: =SUM(E14:E18) | F19: =SUM(F14:F18) | G19: =SUM(G14:G18) | H19: =SUM(H14:H18) | I19: =SUM(I14:I18) | J19: =SUM(J14:J18) | ... AL19: =SUM(AL14:AL18)
B21: DIRECT COSTS
B22: Retail — case management & neutrals | C22: =C8*'Unit Economics'!$D$5*Assumptions!$C$25+C8*'Unit Economics'!$D$6*(1-Assumptions!$C$25)+C7*'Unit Economics'!$D$7 | D22: =D8*'Unit Economics'!$D$5*Assumptions!$C$25+D8*'Unit Economics'!$D$6*(1-Assumptions!$C$25)+D7*'Unit Economics'!$D$7 | E22: =E8*'Unit Economics'!$D$5*Assumptions!$C$25+E8*'Unit Economics'!$D$6*(1-Assumptions!$C$25)+E7*'Unit Economics'!$D$7 | F22: =F8*'Unit Economics'!$D$5*Assumptions!$C$25+F8*'Unit Economics'!$D$6*(1-Assumptions!$C$25)+F7*'Unit Economics'!$D$7 | G22: =G8*'Unit Economics'!$D$5*Assumptions!$C$25+G8*'Unit Economics'!$D$6*(1-Assumptions!$C$25)+G7*'Unit Economics'!$D$7 | H22: =H8*'Unit Economics'!$D$5*Assumptions!$C$25+H8*'Unit Economics'!$D$6*(1-Assumptions!$C$25)+H7*'Unit Economics'!$D$7 | I22: =I8*'Unit Economics'!$D$5*Assumptions!$C$25+I8*'Unit Economics'!$D$6*(1-Assumptions!$C$25)+I7*'Unit Economics'!$D$7 | J22: =J8*'Unit Economics'!$D$5*Assumptions!$C$25+J8*'Unit Economics'!$D$6*(1-Assumptions!$C$25)+J7*'Unit Economics'!$D$7 | ... AL22: =AL8*'Unit Economics'!$D$5*Assumptions!$C$25+AL8*'Unit Economics'!$D$6*(1-Assumptions!$C$25)+AL7*'Unit Economics'!$D$7
B23: Batched days | C23: =C10*'Unit Economics'!$D$8 | D23: =D10*'Unit Economics'!$D$8 | E23: =E10*'Unit Economics'!$D$8 | F23: =F10*'Unit Economics'!$D$8 | G23: =G10*'Unit Economics'!$D$8 | H23: =H10*'Unit Economics'!$D$8 | I23: =I10*'Unit Economics'!$D$8 | J23: =J10*'Unit Economics'!$D$8 | ... AL23: =AL10*'Unit Economics'!$D$8
B24: Commercial | C24: =C11*'Unit Economics'!$D$10 | D24: =D11*'Unit Economics'!$D$10 | E24: =E11*'Unit Economics'!$D$10 | F24: =F11*'Unit Economics'!$D$10 | G24: =G11*'Unit Economics'!$D$10 | H24: =H11*'Unit Economics'!$D$10 | I24: =I11*'Unit Economics'!$D$10 | J24: =J11*'Unit Economics'!$D$10 | ... AL24: =AL11*'Unit Economics'!$D$10
B25: Insurer account management | C25: =C9*Assumptions!$C$33/12 | D25: =D9*Assumptions!$C$33/12 | E25: =E9*Assumptions!$C$33/12 | F25: =F9*Assumptions!$C$33/12 | G25: =G9*Assumptions!$C$33/12 | H25: =H9*Assumptions!$C$33/12 | I25: =I9*Assumptions!$C$33/12 | J25: =J9*Assumptions!$C$33/12 | ... AL25: =AL9*Assumptions!$C$33/12
B26: Total direct cost | C26: =SUM(C22:C25) | D26: =SUM(D22:D25) | E26: =SUM(E22:E25) | F26: =SUM(F22:F25) | G26: =SUM(G22:G25) | H26: =SUM(H22:H25) | I26: =SUM(I22:I25) | J26: =SUM(J22:J25) | ... AL26: =SUM(AL22:AL25)
B27: Contribution | C27: =C19-C26 | D27: =D19-D26 | E27: =E19-E26 | F27: =F19-F26 | G27: =G19-G26 | H27: =H19-H26 | I27: =I19-I26 | J27: =J19-J26 | ... AL27: =AL19-AL26
B29: FIXED COSTS
B30: Total fixed | C30: =(Assumptions!$C$36+Assumptions!$C$37+Assumptions!$C$38+Assumptions!$C$39+Assumptions!$C$40+Assumptions!$C$41+Assumptions!$C$42)*MIN(1,0.55+0.45*C5) | D30: =(Assumptions!$C$36+Assumptions!$C$37+Assumptions!$C$38+Assumptions!$C$39+Assumptions!$C$40+Assumptions!$C$41+Assumptions!$C$42)*MIN(1,0.55+0.45*D5) | E30: =(Assumptions!$C$36+Assumptions!$C$37+Assumptions!$C$38+Assumptions!$C$39+Assumptions!$C$40+Assumptions!$C$41+Assumptions!$C$42)*MIN(1,0.55+0.45*E5) | F30: =(Assumptions!$C$36+Assumptions!$C$37+Assumptions!$C$38+Assumptions!$C$39+Assumptions!$C$40+Assumptions!$C$41+Assumptions!$C$42)*MIN(1,0.55+0.45*F5) | G30: =(Assumptions!$C$36+Assumptions!$C$37+Assumptions!$C$38+Assumptions!$C$39+Assumptions!$C$40+Assumptions!$C$41+Assumptions!$C$42)*MIN(1,0.55+0.45*G5) | H30: =(Assumptions!$C$36+Assumptions!$C$37+Assumptions!$C$38+Assumptions!$C$39+Assumptions!$C$40+Assumptions!$C$41+Assumptions!$C$42)*MIN(1,0.55+0.45*H5) | I30: =(Assumptions!$C$36+Assumptions!$C$37+Assumptions!$C$38+Assumptions!$C$39+Assumptions!$C$40+Assumptions!$C$41+Assumptions!$C$42)*MIN(1,0.55+0.45*I5) | J30: =(Assumptions!$C$36+Assumptions!$C$37+Assumptions!$C$38+Assumptions!$C$39+Assumptions!$C$40+Assumptions!$C$41+Assumptions!$C$42)*MIN(1,0.55+0.45*J5) | ... AL30: =(Assumptions!$C$36+Assumptions!$C$37+Assumptions!$C$38+Assumptions!$C$39+Assumptions!$C$40+Assumptions!$C$41+Assumptions!$C$42)*MIN(1,0.55+0.45*AL5)
B31: EBITDA | C31: =C27-C30 | D31: =D27-D30 | E31: =E27-E30 | F31: =F27-F30 | G31: =G27-G30 | H31: =H27-H30 | I31: =I27-I30 | J31: =J27-J30 | ... AL31: =AL27-AL30
B32: Cumulative EBITDA | C32: =C31 | D32: =C32+D31 | E32: =D32+E31 | F32: =E32+F31 | G32: =F32+G31 | H32: =G32+H31 | I32: =H32+I31 | J32: =I32+J31 | K32: =J32+K31 | ... AL32: =AK32+AL31
B33: Break-even flag | C33: =IF(C31>0,1,9999) | D33: =IF(D31>0,2,9999) | E33: =IF(E31>0,3,9999) | F33: =IF(F31>0,4,9999) | G33: =IF(G31>0,5,9999) | H33: =IF(H31>0,6,9999) | I33: =IF(I31>0,7,9999) | J33: =IF(J31>0,8,9999) | K33: =IF(K31>0,9,9999) | L33: =IF(L31>0,10,9999) | M33: =IF(M31>0,11,9999) | N33: =IF(N31>0,12,9999) | O33: =IF(O31>0,13,9999) | P33: =IF(P31>0,14,9999) | Q33: =IF(Q31>0,15,9999) | R33: =IF(R31>0,16,9999) | S33: =IF(S31>0,17,9999) | T33: =IF(T31>0,18,9999) | U33: =IF(U31>0,19,9999) | V33: =IF(V31>0,20,9999) | W33: =IF(W31>0,21,9999) | X33: =IF(X31>0,22,9999) | Y33: =IF(Y31>0,23,9999) | Z33: =IF(Z31>0,24,9999) | AA33: =IF(AA31>0,25,9999) | AB33: =IF(AB31>0,26,9999) | AC33: =IF(AC31>0,27,9999) | AD33: =IF(AD31>0,28,9999) | AE33: =IF(AE31>0,29,9999) | AF33: =IF(AF31>0,30,9999) | AG33: =IF(AG31>0,31,9999) | AH33: =IF(AH31>0,32,9999) | AI33: =IF(AI31>0,33,9999) | AJ33: =IF(AJ31>0,34,9999) | AK33: =IF(AK31>0,35,9999) | AL33: =IF(AL31>0,36,9999)
B42: Break-even month | C42: =MIN(C33:AL33)
B43: Month-36 annualised revenue | C43: =AL19*12
B44: Month-36 annualised EBITDA | C44: =AL31*12
B45: Recurring share of month-36 revenue (subscriptions + batched days) | C45: =(AL16+AL17)/AL19

Sheet Scenarios
A1: Scenarios
A2: Change the Assumptions to the values below and read the Build-Up outputs. The point of this sheet is the middle column.
B4: Driver | C4: Downside | D4: Base | E4: Upside | F4: Why it matters
B5: Retail matters per month (month 36) | C5: 180 | D5: 320 | E5: 480 | F5: Retail volume drives credibility, not profit
B6: Insurer subscribers | C6: 3 | D6: 9 | E6: 15 | F6: The single most important number in this model
B7: Batched days per month | C7: 3 | D7: 11 | E7: 20 | F7: The highest-margin product; entirely dependent on subscribers
B8: Average annual subscription (₹) | C8: 2200000 | D8: 3400000 | E8: 4600000 | F8: Tier mix
B9: Commercial matters per month | C9: 7 | D9: 16 | E9: 28 | F9: Ad valorem; broker-channel dependent
B10: Fee-waiver share | C10: 0.38 | D10: 0.28 | E10: 0.22 | F10: Higher waivers are a cost we accept, not a failure
B11: Retail settlement rate | C11: 0.44 | D11: 0.55 | E11: 0.64 | F11: Improves with insurer participation
B14: What the downside case says
B15: With two insurer subscribers and one batched day a month, this vertical does not reach EBITDA break-even within 36 months on any realistic retail volume. That is the honest finding, and it should drive the plan: the insurer sale is not an upside lever, it is the business. If two protocols are not signed by month 18, the vertical should be re-scoped as a credibility and referral asset for the platform rather than continued as a standalone P&L.
